Workbook

Sheet POA — Three year summary
A1: POA — Three year summary
A2: POA — Financial Forecast · Main Scenario
A4: Variable / dimension | B4: Forecast year start | C4: Forecast year end | D4: Annual subscription revenue | E4: Annual contingency revenue | F4: Annual total revenue | G4: Annual gross profit | H4: Annual operating overhead | I4: Annual acquisition spend | J4: Annual EBITDA | K4: Annual net cash flow | L4: Year end cash | M4: Year end active protocols | N4: Year end subscription ARR | O4: Year end total annualized run rate
A5: Year 1 | B5: =DATE(2026,10,1) -> 46296 | C5: =DATE(2027,9,1) -> 46631 | D5: =SUM('Model inputs'!B129,'Model inputs'!B130,'Model inputs'!B131) -> 395500 | E5: =SUM('Model inputs'!B132,'Model inputs'!B133,'Model inputs'!B134) -> 51333.123 | F5: =SUM('Model inputs'!B135,'Model inputs'!B136,'Model inputs'!B137) -> 446833.12 | G5: =SUM('Model inputs'!B138,'Model inputs'!B139,'Model inputs'!B140) -> 445939.46 | H5: =SUM('Model inputs'!B141,'Model inputs'!B142,'Model inputs'!B143) -> 327300 | I5: =SUM('Model inputs'!B144,'Model inputs'!B145,'Model inputs'!B146) -> 222333.33 | J5: =SUM('Model inputs'!B147,'Model inputs'!B148,'Model inputs'!B149) -> -103693.88 | K5: =SUM('Model inputs'!B150,'Model inputs'!B151,'Model inputs'!B152) -> -103693.88 | L5: =IF('Model inputs'!B190=0,"",SUM('Model inputs'!B153,'Model inputs'!B154,'Model inputs'!B155,'Model inputs'!B156,'Model inputs'!B157,'Model inputs'!B158,'Model inputs'!B159,'Model inputs'!B160,'Model inputs'!B161,'Model inputs'!B162,'Model inputs'!B163,'Model inputs'!B164,'Model inputs'!B165,'Model inputs'!B166,'Model inputs'!B167,'Model inputs'!B168,'Model inputs'!B169,'Model inputs'!B170,'Model inputs'!B171,'Model inputs'!B172,'Model inputs'!B173,'Model inputs'!B174,'Model inputs'!B175,'Model inputs'!B176,'Model inputs'!B177,'Model inputs'!B178,'Model inputs'!B179,'Model inputs'!B180,'Model inputs'!B181,'Model inputs'!B182,'Model inputs'!B183,'Model inputs'!B184,'Model inputs'!B185,'Model inputs'!B186,'Model inputs'!B187,'Model inputs'!B188,'Model inputs'!B189)) -> 396306.12 | M5: =IF('Model inputs'!B228=0,"",SUM('Model inputs'!B191,'Model inputs'!B192,'Model inputs'!B193,'Model inputs'!B194,'Model inputs'!B195,'Model inputs'!B196,'Model inputs'!B197,'Model inputs'!B198,'Model inputs'!B199,'Model inputs'!B200,'Model inputs'!B201,'Model inputs'!B202,'Model inputs'!B203,'Model inputs'!B204,'Model inputs'!B205,'Model inputs'!B206,'Model inputs'!B207,'Model inputs'!B208,'Model inputs'!B209,'Model inputs'!B210,'Model inputs'!B211,'Model inputs'!B212,'Model inputs'!B213,'Model inputs'!B214,'Model inputs'!B215,'Model inputs'!B216,'Model inputs'!B217,'Model inputs'!B218,'Model inputs'!B219,'Model inputs'!B220,'Model inputs'!B221,'Model inputs'!B222,'Model inputs'!B223,'Model inputs'!B224,'Model inputs'!B225,'Model inputs'!B226,'Model inputs'!B227)) -> 22 | N5: =IF('Model inputs'!B265=0,"",SUM('Model inputs'!B229,'Model inputs'!B230,'Model inputs'!B231,'Model inputs'!B232,'Model inputs'!B233,'Model inputs'!B234,'Model inputs'!B235,'Model inputs'!B236,'Model inputs'!B237,'Model inputs'!B238,'Model inputs'!B239,'Model inputs'!B240,'Model inputs'!B241,'Model inputs'!B242,'Model inputs'!B243,'Model inputs'!B244,'Model inputs'!B245,'Model inputs'!B246,'Model inputs'!B247,'Model inputs'!B248,'Model inputs'!B249,'Model inputs'!B250,'Model inputs'!B251,'Model inputs'!B252,'Model inputs'!B253,'Model inputs'!B254,'Model inputs'!B255,'Model inputs'!B256,'Model inputs'!B257,'Model inputs'!B258,'Model inputs'!B259,'Model inputs'!B260,'Model inputs'!B261,'Model inputs'!B262,'Model inputs'!B263,'Model inputs'!B264)) -> 924000 | O5: =IF('Model inputs'!B302=0,"",SUM('Model inputs'!B266,'Model inputs'!B267,'Model inputs'!B268,'Model inputs'!B269,'Model inputs'!B270,'Model inputs'!B271,'Model inputs'!B272,'Model inputs'!B273,'Model inputs'!B274,'Model inputs'!B275,'Model inputs'!B276,'Model inputs'!B277,'Model inputs'!B278,'Model inputs'!B279,'Model inputs'!B280,'Model inputs'!B281,'Model inputs'!B282,'Model inputs'!B283,'Model inputs'!B284,'Model inputs'!B285,'Model inputs'!B286,'Model inputs'!B287,'Model inputs'!B288,'Model inputs'!B289,'Model inputs'!B290,'Model inputs'!B291,'Model inputs'!B292,'Model inputs'!B293,'Model inputs'!B294,'Model inputs'!B295,'Model inputs'!B296,'Model inputs'!B297,'Model inputs'!B298,'Model inputs'!B299,'Model inputs'!B300,'Model inputs'!B301)) -> 1120000
A6: Year 2 | B6: =DATE(2027,10,1) -> 46661 | C6: =DATE(2028,9,1) -> 46997 | D6: =SUM('Model inputs'!B303,'Model inputs'!B304,'Model inputs'!B305) -> 2677500 | E6: =SUM('Model inputs'!B306,'Model inputs'!B307,'Model inputs'!B308) -> 987359.01 | F6: =SUM('Model inputs'!B309,'Model inputs'!B310,'Model inputs'!B311) -> 3664859 | G6: =SUM('Model inputs'!B312,'Model inputs'!B313,'Model inputs'!B314) -> 3657529.3 | H6: =SUM('Model inputs'!B315,'Model inputs'!B316,'Model inputs'!B317) -> 1198700 | I6: =SUM('Model inputs'!B318,'Model inputs'!B319,'Model inputs'!B320) -> 868085.71 | J6: =SUM('Model inputs'!B321,'Model inputs'!B322,'Model inputs'!B323) -> 1590743.6 | K6: =SUM('Model inputs'!B324,'Model inputs'!B325,'Model inputs'!B326) -> 1590743.6 | L6: =IF('Model inputs'!B364=0,"",SUM('Model inputs'!B327,'Model inputs'!B328,'Model inputs'!B329,'Model inputs'!B330,'Model inputs'!B331,'Model inputs'!B332,'Model inputs'!B333,'Model inputs'!B334,'Model inputs'!B335,'Model inputs'!B336,'Model inputs'!B337,'Model inputs'!B338,'Model inputs'!B339,'Model inputs'!B340,'Model inputs'!B341,'Model inputs'!B342,'Model inputs'!B343,'Model inputs'!B344,'Model inputs'!B345,'Model inputs'!B346,'Model inputs'!B347,'Model inputs'!B348,'Model inputs'!B349,'Model inputs'!B350,'Model inputs'!B351,'Model inputs'!B352,'Model inputs'!B353,'Model inputs'!B354,'Model inputs'!B355,'Model inputs'!B356,'Model inputs'!B357,'Model inputs'!B358,'Model inputs'!B359,'Model inputs'!B360,'Model inputs'!B361,'Model inputs'!B362,'Model inputs'!B363)) -> 1987049.7 | M6: =IF('Model inputs'!B402=0,"",SUM('Model inputs'!B365,'Model inputs'!B366,'Model inputs'!B367,'Model inputs'!B368,'Model inputs'!B369,'Model inputs'!B370,'Model inputs'!B371,'Model inputs'!B372,'Model inputs'!B373,'Model inputs'!B374,'Model inputs'!B375,'Model inputs'!B376,'Model inputs'!B377,'Model inputs'!B378,'Model inputs'!B379,'Model inputs'!B380,'Model inputs'!B381,'Model inputs'!B382,'Model inputs'!B383,'Model inputs'!B384,'Model inputs'!B385,'Model inputs'!B386,'Model inputs'!B387,'Model inputs'!B388,'Model inputs'!B389,'Model inputs'!B390,'Model inputs'!B391,'Model inputs'!B392,'Model inputs'!B393,'Model inputs'!B394,'Model inputs'!B395,'Model inputs'!B396,'Model inputs'!B397,'Model inputs'!B398,'Model inputs'!B399,'Model inputs'!B400,'Model inputs'!B401)) -> 100 | N6: =IF('Model inputs'!B439=0,"",SUM('Model inputs'!B403,'Model inputs'!B404,'Model inputs'!B405,'Model inputs'!B406,'Model inputs'!B407,'Model inputs'!B408,'Model inputs'!B409,'Model inputs'!B410,'Model inputs'!B411,'Model inputs'!B412,'Model inputs'!B413,'Model inputs'!B414,'Model inputs'!B415,'Model inputs'!B416,'Model inputs'!B417,'Model inputs'!B418,'Model inputs'!B419,'Model inputs'!B420,'Model inputs'!B421,'Model inputs'!B422,'Model inputs'!B423,'Model inputs'!B424,'Model inputs'!B425,'Model inputs'!B426,'Model inputs'!B427,'Model inputs'!B428,'Model inputs'!B429,'Model inputs'!B430,'Model inputs'!B431,'Model inputs'!B432,'Model inputs'!B433,'Model inputs'!B434,'Model inputs'!B435,'Model inputs'!B436,'Model inputs'!B437,'Model inputs'!B438)) -> 4200000 | O6: =IF('Model inputs'!B476=0,"",SUM('Model inputs'!B440,'Model inputs'!B441,'Model inputs'!B442,'Model inputs'!B443,'Model inputs'!B444,'Model inputs'!B445,'Model inputs'!B446,'Model inputs'!B447,'Model inputs'!B448,'Model inputs'!B449,'Model inputs'!B450,'Model inputs'!B451,'Model inputs'!B452,'Model inputs'!B453,'Model inputs'!B454,'Model inputs'!B455,'Model inputs'!B456,'Model inputs'!B457,'Model inputs'!B458,'Model inputs'!B459,'Model inputs'!B460,'Model inputs'!B461,'Model inputs'!B462,'Model inputs'!B463,'Model inputs'!B464,'Model inputs'!B465,'Model inputs'!B466,'Model inputs'!B467,'Model inputs'!B468,'Model inputs'!B469,'Model inputs'!B470,'Model inputs'!B471,'Model inputs'!B472,'Model inputs'!B473,'Model inputs'!B474,'Model inputs'!B475)) -> 6000000
A7: Year 3 | B7: =DATE(2028,10,1) -> 47027 | C7: =DATE(2029,9,1) -> 47362 | D7: =SUM('Model inputs'!B477,'Model inputs'!B478,'Model inputs'!B479) -> 5670000 | E7: =SUM('Model inputs'!B480,'Model inputs'!B481,'Model inputs'!B482) -> 2897916.7 | F7: =SUM('Model inputs'!B483,'Model inputs'!B484,'Model inputs'!B485) -> 8567916.7 | G7: =SUM('Model inputs'!B486,'Model inputs'!B487,'Model inputs'!B488) -> 8550780.8 | H7: =SUM('Model inputs'!B489,'Model inputs'!B490,'Model inputs'!B491) -> 2117500 | I7: =SUM('Model inputs'!B492,'Model inputs'!B493,'Model inputs'!B494) -> 893714.29 | J7: =SUM('Model inputs'!B495,'Model inputs'!B496,'Model inputs'!B497) -> 5539566.5 | K7: =SUM('Model inputs'!B498,'Model inputs'!B499,'Model inputs'!B500) -> 5539566.5 | L7: =IF('Model inputs'!B538=0,"",SUM('Model inputs'!B501,'Model inputs'!B502,'Model inputs'!B503,'Model inputs'!B504,'Model inputs'!B505,'Model inputs'!B506,'Model inputs'!B507,'Model inputs'!B508,'Model inputs'!B509,'Model inputs'!B510,'Model inputs'!B511,'Model inputs'!B512,'Model inputs'!B513,'Model inputs'!B514,'Model inputs'!B515,'Model inputs'!B516,'Model inputs'!B517,'Model inputs'!B518,'Model inputs'!B519,'Model inputs'!B520,'Model inputs'!B521,'Model inputs'!B522,'Model inputs'!B523,'Model inputs'!B524,'Model inputs'!B525,'Model inputs'!B526,'Model inputs'!B527,'Model inputs'!B528,'Model inputs'!B529,'Model inputs'!B530,'Model inputs'!B531,'Model inputs'!B532,'Model inputs'!B533,'Model inputs'!B534,'Model inputs'!B535,'Model inputs'!B536,'Model inputs'!B537)) -> 7526616.2 | M7: =IF('Model inputs'!B576=0,"",SUM('Model inputs'!B539,'Model inputs'!B540,'Model inputs'!B541,'Model inputs'!B542,'Model inputs'!B543,'Model inputs'!B544,'Model inputs'!B545,'Model inputs'!B546,'Model inputs'!B547,'Model inputs'!B548,'Model inputs'!B549,'Model inputs'!B550,'Model inputs'!B551,'Model inputs'!B552,'Model inputs'!B553,'Model inputs'!B554,'Model inputs'!B555,'Model inputs'!B556,'Model inputs'!B557,'Model inputs'!B558,'Model inputs'!B559,'Model inputs'!B560,'Model inputs'!B561,'Model inputs'!B562,'Model inputs'!B563,'Model inputs'!B564,'Model inputs'!B565,'Model inputs'!B566,'Model inputs'!B567,'Model inputs'!B568,'Model inputs'!B569,'Model inputs'!B570,'Model inputs'!B571,'Model inputs'!B572,'Model inputs'!B573,'Model inputs'!B574,'Model inputs'!B575)) -> 160 | N7: =IF('Model inputs'!B613=0,"",SUM('Model inputs'!B577,'Model inputs'!B578,'Model inputs'!B579,'Model inputs'!B580,'Model inputs'!B581,'Model inputs'!B582,'Model inputs'!B583,'Model inputs'!B584,'Model inputs'!B585,'Model inputs'!B586,'Model inputs'!B587,'Model inputs'!B588,'Model inputs'!B589,'Model inputs'!B590,'Model inputs'!B591,'Model inputs'!B592,'Model inputs'!B593,'Model inputs'!B594,'Model inputs'!B595,'Model inputs'!B596,'Model inputs'!B597,'Model inputs'!B598,'Model inputs'!B599,'Model inputs'!B600,'Model inputs'!B601,'Model inputs'!B602,'Model inputs'!B603,'Model inputs'!B604,'Model inputs'!B605,'Model inputs'!B606,'Model inputs'!B607,'Model inputs'!B608,'Model inputs'!B609,'Model inputs'!B610,'Model inputs'!B611,'Model inputs'!B612)) -> 6720000 | O7: =IF('Model inputs'!B650=0,"",SUM('Model inputs'!B614,'Model inputs'!B615,'Model inputs'!B616,'Model inputs'!B617,'Model inputs'!B618,'Model inputs'!B619,'Model inputs'!B620,'Model inputs'!B621,'Model inputs'!B622,'Model inputs'!B623,'Model inputs'!B624,'Model inputs'!B625,'Model inputs'!B626,'Model inputs'!B627,'Model inputs'!B628,'Model inputs'!B629,'Model inputs'!B630,'Model inputs'!B631,'Model inputs'!B632,'Model inputs'!B633,'Model inputs'!B634,'Model inputs'!B635,'Model inputs'!B636,'Model inputs'!B637,'Model inputs'!B638,'Model inputs'!B639,'Model inputs'!B640,'Model inputs'!B641,'Model inputs'!B642,'Model inputs'!B643,'Model inputs'!B644,'Model inputs'!B645,'Model inputs'!B646,'Model inputs'!B647,'Model inputs'!B648,'Model inputs'!B649)) -> 10560000

Sheet POA — Monthly financial forecas
A1: POA — Monthly financial forecast
A2: POA — Financial Forecast · Main Scenario
A4: Variable / dimension | B4: 2026-10 | C4: 2026-11 | D4: 2026-12 | E4: 2027-01 | F4: 2027-02 | G4: 2027-03 | H4: 2027-04 | I4: 2027-05 | J4: 2027-06 | K4: 2027-07 | L4: 2027-08 | M4: 2027-09 | N4: 2027-10 | O4: 2027-11 | P4: 2027-12 | Q4: 2028-01 | R4: 2028-02 | S4: 2028-03 | T4: 2028-04 | U4: 2028-05 | V4: 2028-06 | W4: 2028-07 | X4: 2028-08 | Y4: 2028-09 | Z4: 2028-10 | AA4: 2028-11 | AB4: 2028-12 | AC4: 2029-01 | AD4: 2029-02 | AE4: 2029-03 | AF4: 2029-04 | AG4: 2029-05 | AH4: 2029-06 | AI4: 2029-07 | AJ4: 2029-08 | AK4: 2029-09
A5: Forecast month | B5: =DATEDIF(DATE(2026,10,1),DATE(2026,10,1),"M")+1 -> 1 | C5: =DATEDIF(DATE(2026,10,1),DATE(2026,11,1),"M")+1 -> 2 | D5: =DATEDIF(DATE(2026,10,1),DATE(2026,12,1),"M")+1 -> 3 | E5: =DATEDIF(DATE(2026,10,1),DATE(2027,1,1),"M")+1 -> 4 | F5: =DATEDIF(DATE(2026,10,1),DATE(2027,2,1),"M")+1 -> 5 | G5: =DATEDIF(DATE(2026,10,1),DATE(2027,3,1),"M")+1 -> 6 | H5: =DATEDIF(DATE(2026,10,1),DATE(2027,4,1),"M")+1 -> 7 | I5: =DATEDIF(DATE(2026,10,1),DATE(2027,5,1),"M")+1 -> 8 | J5: =DATEDIF(DATE(2026,10,1),DATE(2027,6,1),"M")+1 -> 9 | K5: =DATEDIF(DATE(2026,10,1),DATE(2027,7,1),"M")+1 -> 10 | L5: =DATEDIF(DATE(2026,10,1),DATE(2027,8,1),"M")+1 -> 11 | M5: =DATEDIF(DATE(2026,10,1),DATE(2027,9,1),"M")+1 -> 12 | N5: =DATEDIF(DATE(2026,10,1),DATE(2027,10,1),"M")+1 -> 13 | O5: =DATEDIF(DATE(2026,10,1),DATE(2027,11,1),"M")+1 -> 14 | P5: =DATEDIF(DATE(2026,10,1),DATE(2027,12,1),"M")+1 -> 15 | Q5: =DATEDIF(DATE(2026,10,1),DATE(2028,1,1),"M")+1 -> 16 | R5: =DATEDIF(DATE(2026,10,1),DATE(2028,2,1),"M")+1 -> 17 | S5: =DATEDIF(DATE(2026,10,1),DATE(2028,3,1),"M")+1 -> 18 | T5: =DATEDIF(DATE(2026,10,1),DATE(2028,4,1),"M")+1 -> 19 | U5: =DATEDIF(DATE(2026,10,1),DATE(2028,5,1),"M")+1 -> 20 | V5: =DATEDIF(DATE(2026,10,1),DATE(2028,6,1),"M")+1 -> 21 | W5: =DATEDIF(DATE(2026,10,1),DATE(2028,7,1),"M")+1 -> 22 | X5: =DATEDIF(DATE(2026,10,1),DATE(2028,8,1),"M")+1 -> 23 | Y5: =DATEDIF(DATE(2026,10,1),DATE(2028,9,1),"M")+1 -> 24 | Z5: =DATEDIF(DATE(2026,10,1),DATE(2028,10,1),"M")+1 -> 25 | AA5: =DATEDIF(DATE(2026,10,1),DATE(2028,11,1),"M")+1 -> 26 | AB5: =DATEDIF(DATE(2026,10,1),DATE(2028,12,1),"M")+1 -> 27 | AC5: =DATEDIF(DATE(2026,10,1),DATE(2029,1,1),"M")+1 -> 28 | AD5: =DATEDIF(DATE(2026,10,1),DATE(2029,2,1),"M")+1 -> 29 | AE5: =DATEDIF(DATE(2026,10,1),DATE(2029,3,1),"M")+1 -> 30 | AF5: =DATEDIF(DATE(2026,10,1),DATE(2029,4,1),"M")+1 -> 31 | AG5: =DATEDIF(DATE(2026,10,1),DATE(2029,5,1),"M")+1 -> 32 | AH5: =DATEDIF(DATE(2026,10,1),DATE(2029,6,1),"M")+1 -> 33 | AI5: =DATEDIF(DATE(2026,10,1),DATE(2029,7,1),"M")+1 -> 34 | AJ5: =DATEDIF(DATE(2026,10,1),DATE(2029,8,1),"M")+1 -> 35 | AK5: =DATEDIF(DATE(2026,10,1),DATE(2029,9,1),"M")+1 -> 36
A6: Monthly churn rate | B6: =1/('Model inputs'!AM30*12) -> 0.023809524 | C6: =1/('Model inputs'!AM30*12) -> 0.023809524 | D6: =1/('Model inputs'!AM30*12) -> 0.023809524 | E6: =1/('Model inputs'!AM30*12) -> 0.023809524 | F6: =1/('Model inputs'!AM30*12) -> 0.023809524 | G6: =1/('Model inputs'!AM30*12) -> 0.023809524 | H6: =1/('Model inputs'!AM30*12) -> 0.023809524 | I6: =1/('Model inputs'!AM30*12) -> 0.023809524 | J6: =1/('Model inputs'!AM30*12) -> 0.023809524 | K6: =1/('Model inputs'!AM30*12) -> 0.023809524 | L6: =1/('Model inputs'!AM30*12) -> 0.023809524 | M6: =1/('Model inputs'!AM30*12) -> 0.023809524 | N6: =1/('Model inputs'!AM30*12) -> 0.023809524 | O6: =1/('Model inputs'!AM30*12) -> 0.023809524 | P6: =1/('Model inputs'!AM30*12) -> 0.023809524 | Q6: =1/('Model inputs'!AM30*12) -> 0.023809524 | R6: =1/('Model inputs'!AM30*12) -> 0.023809524 | S6: =1/('Model inputs'!AM30*12) -> 0.023809524 | T6: =1/('Model inputs'!AM30*12) -> 0.023809524 | U6: =1/('Model inputs'!AM30*12) -> 0.023809524 | V6: =1/('Model inputs'!AM30*12) -> 0.023809524 | W6: =1/('Model inputs'!AM30*12) -> 0.023809524 | X6: =1/('Model inputs'!AM30*12) -> 0.023809524 | Y6: =1/('Model inputs'!AM30*12) -> 0.023809524 | Z6: =1/('Model inputs'!AM30*12) -> 0.023809524 | AA6: =1/('Model inputs'!AM30*12) -> 0.023809524 | AB6: =1/('Model inputs'!AM30*12) -> 0.023809524 | AC6: =1/('Model inputs'!AM30*12) -> 0.023809524 | AD6: =1/('Model inputs'!AM30*12) -> 0.023809524 | AE6: =1/('Model inputs'!AM30*12) -> 0.023809524 | AF6: =1/('Model inputs'!AM30*12) -> 0.023809524 | AG6: =1/('Model inputs'!AM30*12) -> 0.023809524 | AH6: =1/('Model inputs'!AM30*12) -> 0.023809524 | AI6: =1/('Model inputs'!AM30*12) -> 0.023809524 | AJ6: =1/('Model inputs'!AM30*12) -> 0.023809524 | AK6: =1/('Model inputs'!AM30*12) -> 0.023809524
A7: Active protocols | B7: =IF(AND('Model inputs'!AM106="",'Model inputs'!B652=""),"",MIN('Model inputs'!AM106,'Model inputs'!B652)) -> 1 | C7: =IF(AND('Model inputs'!AM106="",'Model inputs'!B654=""),"",MIN('Model inputs'!AM106,'Model inputs'!B654)) -> 2 | D7: =IF(AND('Model inputs'!AM106="",'Model inputs'!B656=""),"",MIN('Model inputs'!AM106,'Model inputs'!B656)) -> 3 | E7: =IF(AND('Model inputs'!AM106="",'Model inputs'!B658=""),"",MIN('Model inputs'!AM106,'Model inputs'!B658)) -> 4 | F7: =IF(AND('Model inputs'!AM106="",'Model inputs'!B660=""),"",MIN('Model inputs'!AM106,'Model inputs'!B660)) -> 5 | G7: =IF(AND('Model inputs'!AM106="",'Model inputs'!B662=""),"",MIN('Model inputs'!AM106,'Model inputs'!B662)) -> 6 | H7: =IF(AND('Model inputs'!AM106="",'Model inputs'!B664=""),"",MIN('Model inputs'!AM106,'Model inputs'!B664)) -> 8.6666667 | I7: =IF(AND('Model inputs'!AM106="",'Model inputs'!B666=""),"",MIN('Model inputs'!AM106,'Model inputs'!B666)) -> 11.333333 | J7: =IF(AND('Model inputs'!AM106="",'Model inputs'!B668=""),"",MIN('Model inputs'!AM106,'Model inputs'!B668)) -> 14 | K7: =IF(AND('Model inputs'!AM106="",'Model inputs'!B670=""),"",MIN('Model inputs'!AM106,'Model inputs'!B670)) -> 16.666667 | L7: =IF(AND('Model inputs'!AM106="",'Model inputs'!B672=""),"",MIN('Model inputs'!AM106,'Model inputs'!B672)) -> 19.333333 | M7: =IF(AND('Model inputs'!AM106="",'Model inputs'!B674=""),"",MIN('Model inputs'!AM106,'Model inputs'!B674)) -> 22 | N7: =IF(AND('Model inputs'!AM106="",'Model inputs'!B676=""),"",MIN('Model inputs'!AM106,'Model inputs'!B676)) -> 28.333333 | O7: =IF(AND('Model inputs'!AM106="",'Model inputs'!B678=""),"",MIN('Model inputs'!AM106,'Model inputs'!B678)) -> 34.666667 | P7: =IF(AND('Model inputs'!AM106="",'Model inputs'!B680=""),"",MIN('Model inputs'!AM106,'Model inputs'!B680)) -> 41 | Q7: =IF(AND('Model inputs'!AM106="",'Model inputs'!B682=""),"",MIN('Model inputs'!AM106,'Model inputs'!B682)) -> 47.333333 | R7: =IF(AND('Model inputs'!AM106="",'Model inputs'!B684=""),"",MIN('Model inputs'!AM106,'Model inputs'!B684)) -> 53.666667 | S7: =IF(AND('Model inputs'!AM106="",'Model inputs'!B686=""),"",MIN('Model inputs'!AM106,'Model inputs'!B686)) -> 60 | T7: =IF(AND('Model inputs'!AM106="",'Model inputs'!B688=""),"",MIN('Model inputs'!AM106,'Model inputs'!B688)) -> 66.666667 | U7: =IF(AND('Model inputs'!AM106="",'Model inputs'!B690=""),"",MIN('Model inputs'!AM106,'Model inputs'!B690)) -> 73.333333 | V7: =IF(AND('Model inputs'!AM106="",'Model inputs'!B692=""),"",MIN('Model inputs'!AM106,'Model inputs'!B692)) -> 80 | W7: =IF(AND('Model inputs'!AM106="",'Model inputs'!B694=""),"",MIN('Model inputs'!AM106,'Model inputs'!B694)) -> 86.666667 | X7: =IF(AND('Model inputs'!AM106="",'Model inputs'!B696=""),"",MIN('Model inputs'!AM106,'Model inputs'!B696)) -> 93.333333 | Y7: =IF(AND('Model inputs'!AM106="",'Model inputs'!B698=""),"",MIN('Model inputs'!AM106,'Model inputs'!B698)) -> 100 | Z7: =IF(AND('Model inputs'!AM106="",'Model inputs'!B700=""),"",MIN('Model inputs'!AM106,'Model inputs'!B700)) -> 105.83333 | AA7: =IF(AND('Model inputs'!AM106="",'Model inputs'!B702=""),"",MIN('Model inputs'!AM106,'Model inputs'!B702)) -> 111.66667 | AB7: =IF(AND('Model inputs'!AM106="",'Model inputs'!B704=""),"",MIN('Model inputs'!AM106,'Model inputs'!B704)) -> 117.5 | AC7: =IF(AND('Model inputs'!AM106="",'Model inputs'!B706=""),"",MIN('Model inputs'!AM106,'Model inputs'!B706)) -> 123.33333 | AD7: =IF(AND('Model inputs'!AM106="",'Model inputs'!B708=""),"",MIN('Model inputs'!AM106,'Model inputs'!B708)) -> 129.16667 | AE7: =IF(AND('Model inputs'!AM106="",'Model inputs'!B710=""),"",MIN('Model inputs'!AM106,'Model inputs'!B710)) -> 135 | AF7: =IF(AND('Model inputs'!AM106="",'Model inputs'!B712=""),"",MIN('Model inputs'!AM106,'Model inputs'!B712)) -> 139.16667 | AG7: =IF(AND('Model inputs'!AM106="",'Model inputs'!B714=""),"",MIN('Model inputs'!AM106,'Model inputs'!B714)) -> 143.33333 | AH7: =IF(AND('Model inputs'!AM106="",'Model inputs'!B716=""),"",MIN('Model inputs'!AM106,'Model inputs'!B716)) -> 147.5 | AI7: =IF(AND('Model inputs'!AM106="",'Model inputs'!B718=""),"",MIN('Model inputs'!AM106,'Model inputs'!B718)) -> 151.66667 | AJ7: =IF(AND('Model inputs'!AM106="",'Model inputs'!B720=""),"",MIN('Model inputs'!AM106,'Model inputs'!B720)) -> 155.83333 | AK7: =IF(AND('Model inputs'!AM106="",'Model inputs'!B722=""),"",MIN('Model inputs'!AM106,'Model inputs'!B722)) -> 160
A8: Opening active protocols | B8: =IF('Model inputs'!B7="","",'Model inputs'!B7) -> 0 | C8: =IF('POA — Monthly financial forecas'!B7="","",'POA — Monthly financial forecas'!B7) -> 1 | D8: =IF('POA — Monthly financial forecas'!C7="","",'POA — Monthly financial forecas'!C7) -> 2 | E8: =IF('POA — Monthly financial forecas'!D7="","",'POA — Monthly financial forecas'!D7) -> 3 | F8: =IF('POA — Monthly financial forecas'!E7="","",'POA — Monthly financial forecas'!E7) -> 4 | G8: =IF('POA — Monthly financial forecas'!F7="","",'POA — Monthly financial forecas'!F7) -> 5 | H8: =IF('POA — Monthly financial forecas'!G7="","",'POA — Monthly financial forecas'!G7) -> 6 | I8: =IF('POA — Monthly financial forecas'!H7="","",'POA — Monthly financial forecas'!H7) -> 8.6666667 | J8: =IF('POA — Monthly financial forecas'!I7="","",'POA — Monthly financial forecas'!I7) -> 11.333333 | ... AK8: =IF('POA — Monthly financial forecas'!AJ7="","",'POA — Monthly financial forecas'!AJ7) -> 155.83333
A9: Churned protocols | B9: ='POA — Monthly financial forecas'!B8*'POA — Monthly financial forecas'!B6 -> 0 | C9: ='POA — Monthly financial forecas'!C8*'POA — Monthly financial forecas'!C6 -> 0.023809524 | D9: ='POA — Monthly financial forecas'!D8*'POA — Monthly financial forecas'!D6 -> 0.047619048 | E9: ='POA — Monthly financial forecas'!E8*'POA — Monthly financial forecas'!E6 -> 0.071428571 | F9: ='POA — Monthly financial forecas'!F8*'POA — Monthly financial forecas'!F6 -> 0.095238095 | G9: ='POA — Monthly financial forecas'!G8*'POA — Monthly financial forecas'!G6 -> 0.11904762 | H9: ='POA — Monthly financial forecas'!H8*'POA — Monthly financial forecas'!H6 -> 0.14285714 | I9: ='POA — Monthly financial forecas'!I8*'POA — Monthly financial forecas'!I6 -> 0.20634921 | ... AK9: ='POA — Monthly financial forecas'!AK8*'POA — Monthly financial forecas'!AK6 -> 3.7103175
A10: Net protocol additions | B10: ='POA — Monthly financial forecas'!B7-'POA — Monthly financial forecas'!B8 -> 1 | C10: ='POA — Monthly financial forecas'!C7-'POA — Monthly financial forecas'!C8 -> 1 | D10: ='POA — Monthly financial forecas'!D7-'POA — Monthly financial forecas'!D8 -> 1 | E10: ='POA — Monthly financial forecas'!E7-'POA — Monthly financial forecas'!E8 -> 1 | F10: ='POA — Monthly financial forecas'!F7-'POA — Monthly financial forecas'!F8 -> 1 | G10: ='POA — Monthly financial forecas'!G7-'POA — Monthly financial forecas'!G8 -> 1 | H10: ='POA — Monthly financial forecas'!H7-'POA — Monthly financial forecas'!H8 -> 2.6666667 | I10: ='POA — Monthly financial forecas'!I7-'POA — Monthly financial forecas'!I8 -> 2.6666667 | ... AK10: ='POA — Monthly financial forecas'!AK7-'POA — Monthly financial forecas'!AK8 -> 4.1666667
A11: Gross acquired protocols | B11: =MAX('POA — Monthly financial forecas'!B10+'POA — Monthly financial forecas'!B9,0) -> 1 | C11: =MAX('POA — Monthly financial forecas'!C10+'POA — Monthly financial forecas'!C9,0) -> 1.0238095 | D11: =MAX('POA — Monthly financial forecas'!D10+'POA — Monthly financial forecas'!D9,0) -> 1.047619 | E11: =MAX('POA — Monthly financial forecas'!E10+'POA — Monthly financial forecas'!E9,0) -> 1.0714286 | F11: =MAX('POA — Monthly financial forecas'!F10+'POA — Monthly financial forecas'!F9,0) -> 1.0952381 | G11: =MAX('POA — Monthly financial forecas'!G10+'POA — Monthly financial forecas'!G9,0) -> 1.1190476 | H11: =MAX('POA — Monthly financial forecas'!H10+'POA — Monthly financial forecas'!H9,0) -> 2.8095238 | I11: =MAX('POA — Monthly financial forecas'!I10+'POA — Monthly financial forecas'!I9,0) -> 2.8730159 | ... AK11: =MAX('POA — Monthly financial forecas'!AK10+'POA — Monthly financial forecas'!AK9,0) -> 7.8769841
A12: Market penetration | B12: ='POA — Monthly financial forecas'!B7/'Model inputs'!AM106 -> 0.005 | C12: ='POA — Monthly financial forecas'!C7/'Model inputs'!AM106 -> 0.01 | D12: ='POA — Monthly financial forecas'!D7/'Model inputs'!AM106 -> 0.015 | E12: ='POA — Monthly financial forecas'!E7/'Model inputs'!AM106 -> 0.02 | F12: ='POA — Monthly financial forecas'!F7/'Model inputs'!AM106 -> 0.025 | G12: ='POA — Monthly financial forecas'!G7/'Model inputs'!AM106 -> 0.03 | H12: ='POA — Monthly financial forecas'!H7/'Model inputs'!AM106 -> 0.043333333 | I12: ='POA — Monthly financial forecas'!I7/'Model inputs'!AM106 -> 0.056666667 | J12: ='POA — Monthly financial forecas'!J7/'Model inputs'!AM106 -> 0.07 | K12: ='POA — Monthly financial forecas'!K7/'Model inputs'!AM106 -> 0.083333333 | L12: ='POA — Monthly financial forecas'!L7/'Model inputs'!AM106 -> 0.096666667 | M12: ='POA — Monthly financial forecas'!M7/'Model inputs'!AM106 -> 0.11 | N12: ='POA — Monthly financial forecas'!N7/'Model inputs'!AM106 -> 0.14166667 | O12: ='POA — Monthly financial forecas'!O7/'Model inputs'!AM106 -> 0.17333333 | P12: ='POA — Monthly financial forecas'!P7/'Model inputs'!AM106 -> 0.205 | Q12: ='POA — Monthly financial forecas'!Q7/'Model inputs'!AM106 -> 0.23666667 | R12: ='POA — Monthly financial forecas'!R7/'Model inputs'!AM106 -> 0.26833333 | S12: ='POA — Monthly financial forecas'!S7/'Model inputs'!AM106 -> 0.3 | T12: ='POA — Monthly financial forecas'!T7/'Model inputs'!AM106 -> 0.33333333 | U12: ='POA — Monthly financial forecas'!U7/'Model inputs'!AM106 -> 0.36666667 | V12: ='POA — Monthly financial forecas'!V7/'Model inputs'!AM106 -> 0.4 | W12: ='POA — Monthly financial forecas'!W7/'Model inputs'!AM106 -> 0.43333333 | X12: ='POA — Monthly financial forecas'!X7/'Model inputs'!AM106 -> 0.46666667 | Y12: ='POA — Monthly financial forecas'!Y7/'Model inputs'!AM106 -> 0.5 | Z12: ='POA — Monthly financial forecas'!Z7/'Model inputs'!AM106 -> 0.52916667 | AA12: ='POA — Monthly financial forecas'!AA7/'Model inputs'!AM106 -> 0.55833333 | AB12: ='POA — Monthly financial forecas'!AB7/'Model inputs'!AM106 -> 0.5875 | AC12: ='POA — Monthly financial forecas'!AC7/'Model inputs'!AM106 -> 0.61666667 | AD12: ='POA — Monthly financial forecas'!AD7/'Model inputs'!AM106 -> 0.64583333 | AE12: ='POA — Monthly financial forecas'!AE7/'Model inputs'!AM106 -> 0.675 | AF12: ='POA — Monthly financial forecas'!AF7/'Model inputs'!AM106 -> 0.69583333 | AG12: ='POA — Monthly financial forecas'!AG7/'Model inputs'!AM106 -> 0.71666667 | AH12: ='POA — Monthly financial forecas'!AH7/'Model inputs'!AM106 -> 0.7375 | AI12: ='POA — Monthly financial forecas'!AI7/'Model inputs'!AM106 -> 0.75833333 | AJ12: ='POA — Monthly financial forecas'!AJ7/'Model inputs'!AM106 -> 0.77916667 | AK12: ='POA — Monthly financial forecas'!AK7/'Model inputs'!AM106 -> 0.8
A13: Contingency revenue per active protocol | B13: =IF('Model inputs'!B723="",0,'Model inputs'!B723)/'Model inputs'!AM9*'Model inputs'!AM14*'Model inputs'!AM74 -> 20.833333 | C13: =IF('Model inputs'!B724="",0,'Model inputs'!B724)/'Model inputs'!AM9*'Model inputs'!AM14*'Model inputs'!AM74 -> 41.666667 | D13: =IF('Model inputs'!B725="",0,'Model inputs'!B725)/'Model inputs'!AM9*'Model inputs'!AM14*'Model inputs'!AM74 -> 62.5 | E13: =IF('Model inputs'!B726="",0,'Model inputs'!B726)/'Model inputs'!AM9*'Model inputs'!AM14*'Model inputs'!AM74 -> 83.333333 | F13: =IF('Model inputs'!B727="",0,'Model inputs'!B727)/'Model inputs'!AM9*'Model inputs'!AM14*'Model inputs'!AM74 -> 104.16667 | G13: =IF('Model inputs'!B728="",0,'Model inputs'!B728)/'Model inputs'!AM9*'Model inputs'!AM14*'Model inputs'!AM74 -> 125 | H13: =IF('Model inputs'!B729="",0,'Model inputs'!B729)/'Model inputs'!AM9*'Model inputs'!AM14*'Model inputs'!AM74 -> 227.90404 | I13: =IF('Model inputs'!B730="",0,'Model inputs'!B730)/'Model inputs'!AM9*'Model inputs'!AM14*'Model inputs'!AM74 -> 330.80808 | J13: =IF('Model inputs'!B731="",0,'Model inputs'!B731)/'Model inputs'!AM9*'Model inputs'!AM14*'Model inputs'!AM74 -> 433.71212 | K13: =IF('Model inputs'!B732="",0,'Model inputs'!B732)/'Model inputs'!AM9*'Model inputs'!AM14*'Model inputs'!AM74 -> 536.61616 | L13: =IF('Model inputs'!B733="",0,'Model inputs'!B733)/'Model inputs'!AM9*'Model inputs'!AM14*'Model inputs'!AM74 -> 639.5202 | M13: =IF('Model inputs'!B734="",0,'Model inputs'!B734)/'Model inputs'!AM9*'Model inputs'!AM14*'Model inputs'!AM74 -> 742.42424 | N13: =IF('Model inputs'!B735="",0,'Model inputs'!B735)/'Model inputs'!AM9*'Model inputs'!AM14*'Model inputs'!AM74 -> 827.0202 | O13: =IF('Model inputs'!B736="",0,'Model inputs'!B736)/'Model inputs'!AM9*'Model inputs'!AM14*'Model inputs'!AM74 -> 911.61616 | P13: =IF('Model inputs'!B737="",0,'Model inputs'!B737)/'Model inputs'!AM9*'Model inputs'!AM14*'Model inputs'!AM74 -> 996.21212 | Q13: =IF('Model inputs'!B738="",0,'Model inputs'!B738)/'Model inputs'!AM9*'Model inputs'!AM14*'Model inputs'!AM74 -> 1080.8081 | R13: =IF('Model inputs'!B739="",0,'Model inputs'!B739)/'Model inputs'!AM9*'Model inputs'!AM14*'Model inputs'!AM74 -> 1165.404 | S13: =IF('Model inputs'!B740="",0,'Model inputs'!B740)/'Model inputs'!AM9*'Model inputs'!AM14*'Model inputs'!AM74 -> 1250 | T13: =IF('Model inputs'!B741="",0,'Model inputs'!B741)/'Model inputs'!AM9*'Model inputs'!AM14*'Model inputs'!AM74 -> 1291.6667 | U13: =IF('Model inputs'!B742="",0,'Model inputs'!B742)/'Model inputs'!AM9*'Model inputs'!AM14*'Model inputs'!AM74 -> 1333.3333 | V13: =IF('Model inputs'!B743="",0,'Model inputs'!B743)/'Model inputs'!AM9*'Model inputs'!AM14*'Model inputs'!AM74 -> 1375 | W13: =IF('Model inputs'!B744="",0,'Model inputs'!B744)/'Model inputs'!AM9*'Model inputs'!AM14*'Model inputs'!AM74 -> 1416.6667 | X13: =IF('Model inputs'!B745="",0,'Model inputs'!B745)/'Model inputs'!AM9*'Model inputs'!AM14*'Model inputs'!AM74 -> 1458.3333 | Y13: =IF('Model inputs'!B746="",0,'Model inputs'!B746)/'Model inputs'!AM9*'Model inputs'!AM14*'Model inputs'!AM74 -> 1500 | Z13: =IF('Model inputs'!B747="",0,'Model inputs'!B747)/'Model inputs'!AM9*'Model inputs'!AM14*'Model inputs'!AM74 -> 1541.6667 | AA13: =IF('Model inputs'!B748="",0,'Model inputs'!B748)/'Model inputs'!AM9*'Model inputs'!AM14*'Model inputs'!AM74 -> 1583.3333 | AB13: =IF('Model inputs'!B749="",0,'Model inputs'!B749)/'Model inputs'!AM9*'Model inputs'!AM14*'Model inputs'!AM74 -> 1625 | AC13: =IF('Model inputs'!B750="",0,'Model inputs'!B750)/'Model inputs'!AM9*'Model inputs'!AM14*'Model inputs'!AM74 -> 1666.6667 | AD13: =IF('Model inputs'!B751="",0,'Model inputs'!B751)/'Model inputs'!AM9*'Model inputs'!AM14*'Model inputs'!AM74 -> 1708.3333 | AE13: =IF('Model inputs'!B752="",0,'Model inputs'!B752)/'Model inputs'!AM9*'Model inputs'!AM14*'Model inputs'!AM74 -> 1750 | AF13: =IF('Model inputs'!B753="",0,'Model inputs'!B753)/'Model inputs'!AM9*'Model inputs'!AM14*'Model inputs'!AM74 -> 1791.6667 | AG13: =IF('Model inputs'!B754="",0,'Model inputs'!B754)/'Model inputs'!AM9*'Model inputs'!AM14*'Model inputs'!AM74 -> 1833.3333 | AH13: =IF('Model inputs'!B755="",0,'Model inputs'!B755)/'Model inputs'!AM9*'Model inputs'!AM14*'Model inputs'!AM74 -> 1875 | AI13: =IF('Model inputs'!B756="",0,'Model inputs'!B756)/'Model inputs'!AM9*'Model inputs'!AM14*'Model inputs'!AM74 -> 1916.6667 | AJ13: =IF('Model inputs'!B757="",0,'Model inputs'!B757)/'Model inputs'!AM9*'Model inputs'!AM14*'Model inputs'!AM74 -> 1958.3333 | AK13: =IF('Model inputs'!B758="",0,'Model inputs'!B758)/'Model inputs'!AM9*'Model inputs'!AM14*'Model inputs'!AM74 -> 2000
A14: Active protocols by segment | B14: =SUM('POA — Monthly financial forecas'!B15,'POA — Monthly financial forecas'!B16,'POA — Monthly financial forecas'!B17) -> 1 | C14: =SUM('POA — Monthly financial forecas'!C15,'POA — Monthly financial forecas'!C16,'POA — Monthly financial forecas'!C17) -> 2 | D14: =SUM('POA — Monthly financial forecas'!D15,'POA — Monthly financial forecas'!D16,'POA — Monthly financial forecas'!D17) -> 3 | E14: =SUM('POA — Monthly financial forecas'!E15,'POA — Monthly financial forecas'!E16,'POA — Monthly financial forecas'!E17) -> 4 | F14: =SUM('POA — Monthly financial forecas'!F15,'POA — Monthly financial forecas'!F16,'POA — Monthly financial forecas'!F17) -> 5 | G14: =SUM('POA — Monthly financial forecas'!G15,'POA — Monthly financial forecas'!G16,'POA — Monthly financial forecas'!G17) -> 6 | H14: =SUM('POA — Monthly financial forecas'!H15,'POA — Monthly financial forecas'!H16,'POA — Monthly financial forecas'!H17) -> 8.6666667 | I14: =SUM('POA — Monthly financial forecas'!I15,'POA — Monthly financial forecas'!I16,'POA — Monthly financial forecas'!I17) -> 11.333333 | ... AK14: =SUM('POA — Monthly financial forecas'!AK15,'POA — Monthly financial forecas'!AK16,'POA — Monthly financial forecas'!AK17) -> 160
A15: DEX | B15: ='POA — Monthly financial forecas'!B7*'Model inputs'!AM76 -> 0.3 | C15: ='POA — Monthly financial forecas'!C7*'Model inputs'!AM76 -> 0.6 | D15: ='POA — Monthly financial forecas'!D7*'Model inputs'!AM76 -> 0.9 | E15: ='POA — Monthly financial forecas'!E7*'Model inputs'!AM76 -> 1.2 | F15: ='POA — Monthly financial forecas'!F7*'Model inputs'!AM76 -> 1.5 | G15: ='POA — Monthly financial forecas'!G7*'Model inputs'!AM76 -> 1.8 | H15: ='POA — Monthly financial forecas'!H7*'Model inputs'!AM76 -> 2.6 | I15: ='POA — Monthly financial forecas'!I7*'Model inputs'!AM76 -> 3.4 | J15: ='POA — Monthly financial forecas'!J7*'Model inputs'!AM76 -> 4.2 | K15: ='POA — Monthly financial forecas'!K7*'Model inputs'!AM76 -> 5 | L15: ='POA — Monthly financial forecas'!L7*'Model inputs'!AM76 -> 5.8 | M15: ='POA — Monthly financial forecas'!M7*'Model inputs'!AM76 -> 6.6 | N15: ='POA — Monthly financial forecas'!N7*'Model inputs'!AM76 -> 8.5 | O15: ='POA — Monthly financial forecas'!O7*'Model inputs'!AM76 -> 10.4 | P15: ='POA — Monthly financial forecas'!P7*'Model inputs'!AM76 -> 12.3 | Q15: ='POA — Monthly financial forecas'!Q7*'Model inputs'!AM76 -> 14.2 | R15: ='POA — Monthly financial forecas'!R7*'Model inputs'!AM76 -> 16.1 | S15: ='POA — Monthly financial forecas'!S7*'Model inputs'!AM76 -> 18 | T15: ='POA — Monthly financial forecas'!T7*'Model inputs'!AM76 -> 20 | U15: ='POA — Monthly financial forecas'!U7*'Model inputs'!AM76 -> 22 | V15: ='POA — Monthly financial forecas'!V7*'Model inputs'!AM76 -> 24 | W15: ='POA — Monthly financial forecas'!W7*'Model inputs'!AM76 -> 26 | X15: ='POA — Monthly financial forecas'!X7*'Model inputs'!AM76 -> 28 | Y15: ='POA — Monthly financial forecas'!Y7*'Model inputs'!AM76 -> 30 | Z15: ='POA — Monthly financial forecas'!Z7*'Model inputs'!AM76 -> 31.75 | AA15: ='POA — Monthly financial forecas'!AA7*'Model inputs'!AM76 -> 33.5 | AB15: ='POA — Monthly financial forecas'!AB7*'Model inputs'!AM76 -> 35.25 | AC15: ='POA — Monthly financial forecas'!AC7*'Model inputs'!AM76 -> 37 | AD15: ='POA — Monthly financial forecas'!AD7*'Model inputs'!AM76 -> 38.75 | AE15: ='POA — Monthly financial forecas'!AE7*'Model inputs'!AM76 -> 40.5 | AF15: ='POA — Monthly financial forecas'!AF7*'Model inputs'!AM76 -> 41.75 | AG15: ='POA — Monthly financial forecas'!AG7*'Model inputs'!AM76 -> 43 | AH15: ='POA — Monthly financial forecas'!AH7*'Model inputs'!AM76 -> 44.25 | AI15: ='POA — Monthly financial forecas'!AI7*'Model inputs'!AM76 -> 45.5 | AJ15: ='POA — Monthly financial forecas'!AJ7*'Model inputs'!AM76 -> 46.75 | AK15: ='POA — Monthly financial forecas'!AK7*'Model inputs'!AM76 -> 48
A16: Lending | B16: ='POA — Monthly financial forecas'!B7*'Model inputs'!AM77 -> 0.4 | C16: ='POA — Monthly financial forecas'!C7*'Model inputs'!AM77 -> 0.8 | D16: ='POA — Monthly financial forecas'!D7*'Model inputs'!AM77 -> 1.2 | E16: ='POA — Monthly financial forecas'!E7*'Model inputs'!AM77 -> 1.6 | F16: ='POA — Monthly financial forecas'!F7*'Model inputs'!AM77 -> 2 | G16: ='POA — Monthly financial forecas'!G7*'Model inputs'!AM77 -> 2.4 | H16: ='POA — Monthly financial forecas'!H7*'Model inputs'!AM77 -> 3.4666667 | I16: ='POA — Monthly financial forecas'!I7*'Model inputs'!AM77 -> 4.5333333 | J16: ='POA — Monthly financial forecas'!J7*'Model inputs'!AM77 -> 5.6 | K16: ='POA — Monthly financial forecas'!K7*'Model inputs'!AM77 -> 6.6666667 | L16: ='POA — Monthly financial forecas'!L7*'Model inputs'!AM77 -> 7.7333333 | M16: ='POA — Monthly financial forecas'!M7*'Model inputs'!AM77 -> 8.8 | N16: ='POA — Monthly financial forecas'!N7*'Model inputs'!AM77 -> 11.333333 | O16: ='POA — Monthly financial forecas'!O7*'Model inputs'!AM77 -> 13.866667 | P16: ='POA — Monthly financial forecas'!P7*'Model inputs'!AM77 -> 16.4 | Q16: ='POA — Monthly financial forecas'!Q7*'Model inputs'!AM77 -> 18.933333 | R16: ='POA — Monthly financial forecas'!R7*'Model inputs'!AM77 -> 21.466667 | S16: ='POA — Monthly financial forecas'!S7*'Model inputs'!AM77 -> 24 | T16: ='POA — Monthly financial forecas'!T7*'Model inputs'!AM77 -> 26.666667 | U16: ='POA — Monthly financial forecas'!U7*'Model inputs'!AM77 -> 29.333333 | V16: ='POA — Monthly financial forecas'!V7*'Model inputs'!AM77 -> 32 | W16: ='POA — Monthly financial forecas'!W7*'Model inputs'!AM77 -> 34.666667 | X16: ='POA — Monthly financial forecas'!X7*'Model inputs'!AM77 -> 37.333333 | Y16: ='POA — Monthly financial forecas'!Y7*'Model inputs'!AM77 -> 40 | Z16: ='POA — Monthly financial forecas'!Z7*'Model inputs'!AM77 -> 42.333333 | AA16: ='POA — Monthly financial forecas'!AA7*'Model inputs'!AM77 -> 44.666667 | AB16: ='POA — Monthly financial forecas'!AB7*'Model inputs'!AM77 -> 47 | AC16: ='POA — Monthly financial forecas'!AC7*'Model inputs'!AM77 -> 49.333333 | AD16: ='POA — Monthly financial forecas'!AD7*'Model inputs'!AM77 -> 51.666667 | AE16: ='POA — Monthly financial forecas'!AE7*'Model inputs'!AM77 -> 54 | AF16: ='POA — Monthly financial forecas'!AF7*'Model inputs'!AM77 -> 55.666667 | AG16: ='POA — Monthly financial forecas'!AG7*'Model inputs'!AM77 -> 57.333333 | AH16: ='POA — Monthly financial forecas'!AH7*'Model inputs'!AM77 -> 59 | AI16: ='POA — Monthly financial forecas'!AI7*'Model inputs'!AM77 -> 60.666667 | AJ16: ='POA — Monthly financial forecas'!AJ7*'Model inputs'!AM77 -> 62.333333 | AK16: ='POA — Monthly financial forecas'!AK7*'Model inputs'!AM77 -> 64
A17: Liquid staking | B17: ='POA — Monthly financial forecas'!B7*'Model inputs'!AM78 -> 0.3 | C17: ='POA — Monthly financial forecas'!C7*'Model inputs'!AM78 -> 0.6 | D17: ='POA — Monthly financial forecas'!D7*'Model inputs'!AM78 -> 0.9 | E17: ='POA — Monthly financial forecas'!E7*'Model inputs'!AM78 -> 1.2 | F17: ='POA — Monthly financial forecas'!F7*'Model inputs'!AM78 -> 1.5 | G17: ='POA — Monthly financial forecas'!G7*'Model inputs'!AM78 -> 1.8 | H17: ='POA — Monthly financial forecas'!H7*'Model inputs'!AM78 -> 2.6 | I17: ='POA — Monthly financial forecas'!I7*'Model inputs'!AM78 -> 3.4 | J17: ='POA — Monthly financial forecas'!J7*'Model inputs'!AM78 -> 4.2 | K17: ='POA — Monthly financial forecas'!K7*'Model inputs'!AM78 -> 5 | L17: ='POA — Monthly financial forecas'!L7*'Model inputs'!AM78 -> 5.8 | M17: ='POA — Monthly financial forecas'!M7*'Model inputs'!AM78 -> 6.6 | N17: ='POA — Monthly financial forecas'!N7*'Model inputs'!AM78 -> 8.5 | O17: ='POA — Monthly financial forecas'!O7*'Model inputs'!AM78 -> 10.4 | P17: ='POA — Monthly financial forecas'!P7*'Model inputs'!AM78 -> 12.3 | Q17: ='POA — Monthly financial forecas'!Q7*'Model inputs'!AM78 -> 14.2 | R17: ='POA — Monthly financial forecas'!R7*'Model inputs'!AM78 -> 16.1 | S17: ='POA — Monthly financial forecas'!S7*'Model inputs'!AM78 -> 18 | T17: ='POA — Monthly financial forecas'!T7*'Model inputs'!AM78 -> 20 | U17: ='POA — Monthly financial forecas'!U7*'Model inputs'!AM78 -> 22 | V17: ='POA — Monthly financial forecas'!V7*'Model inputs'!AM78 -> 24 | W17: ='POA — Monthly financial forecas'!W7*'Model inputs'!AM78 -> 26 | X17: ='POA — Monthly financial forecas'!X7*'Model inputs'!AM78 -> 28 | Y17: ='POA — Monthly financial forecas'!Y7*'Model inputs'!AM78 -> 30 | Z17: ='POA — Monthly financial forecas'!Z7*'Model inputs'!AM78 -> 31.75 | AA17: ='POA — Monthly financial forecas'!AA7*'Model inputs'!AM78 -> 33.5 | AB17: ='POA — Monthly financial forecas'!AB7*'Model inputs'!AM78 -> 35.25 | AC17: ='POA — Monthly financial forecas'!AC7*'Model inputs'!AM78 -> 37 | AD17: ='POA — Monthly financial forecas'!AD7*'Model inputs'!AM78 -> 38.75 | AE17: ='POA — Monthly financial forecas'!AE7*'Model inputs'!AM78 -> 40.5 | AF17: ='POA — Monthly financial forecas'!AF7*'Model inputs'!AM78 -> 41.75 | AG17: ='POA — Monthly financial forecas'!AG7*'Model inputs'!AM78 -> 43 | AH17: ='POA — Monthly financial forecas'!AH7*'Model inputs'!AM78 -> 44.25 | AI17: ='POA — Monthly financial forecas'!AI7*'Model inputs'!AM78 -> 45.5 | AJ17: ='POA — Monthly financial forecas'!AJ7*'Model inputs'!AM78 -> 46.75 | AK17: ='POA — Monthly financial forecas'!AK7*'Model inputs'!AM78 -> 48
A18: Subscription MRR | B18: =SUM('POA — Monthly financial forecas'!B19,'POA — Monthly financial forecas'!B20,'POA — Monthly financial forecas'!B21) -> 3500 | C18: =SUM('POA — Monthly financial forecas'!C19,'POA — Monthly financial forecas'!C20,'POA — Monthly financial forecas'!C21) -> 7000 | D18: =SUM('POA — Monthly financial forecas'!D19,'POA — Monthly financial forecas'!D20,'POA — Monthly financial forecas'!D21) -> 10500 | E18: =SUM('POA — Monthly financial forecas'!E19,'POA — Monthly financial forecas'!E20,'POA — Monthly financial forecas'!E21) -> 14000 | F18: =SUM('POA — Monthly financial forecas'!F19,'POA — Monthly financial forecas'!F20,'POA — Monthly financial forecas'!F21) -> 17500 | G18: =SUM('POA — Monthly financial forecas'!G19,'POA — Monthly financial forecas'!G20,'POA — Monthly financial forecas'!G21) -> 21000 | H18: =SUM('POA — Monthly financial forecas'!H19,'POA — Monthly financial forecas'!H20,'POA — Monthly financial forecas'!H21) -> 30333.333 | I18: =SUM('POA — Monthly financial forecas'!I19,'POA — Monthly financial forecas'!I20,'POA — Monthly financial forecas'!I21) -> 39666.667 | ... AK18: =SUM('POA — Monthly financial forecas'!AK19,'POA — Monthly financial forecas'!AK20,'POA — Monthly financial forecas'!AK21) -> 560000
A19: DEX | B19: ='POA — Monthly financial forecas'!B15*'Model inputs'!AM43 -> 1050 | C19: ='POA — Monthly financial forecas'!C15*'Model inputs'!AM43 -> 2100 | D19: ='POA — Monthly financial forecas'!D15*'Model inputs'!AM43 -> 3150 | E19: ='POA — Monthly financial forecas'!E15*'Model inputs'!AM43 -> 4200 | F19: ='POA — Monthly financial forecas'!F15*'Model inputs'!AM43 -> 5250 | G19: ='POA — Monthly financial forecas'!G15*'Model inputs'!AM43 -> 6300 | H19: ='POA — Monthly financial forecas'!H15*'Model inputs'!AM43 -> 9100 | I19: ='POA — Monthly financial forecas'!I15*'Model inputs'!AM43 -> 11900 | J19: ='POA — Monthly financial forecas'!J15*'Model inputs'!AM43 -> 14700 | K19: ='POA — Monthly financial forecas'!K15*'Model inputs'!AM43 -> 17500 | L19: ='POA — Monthly financial forecas'!L15*'Model inputs'!AM43 -> 20300 | M19: ='POA — Monthly financial forecas'!M15*'Model inputs'!AM43 -> 23100 | N19: ='POA — Monthly financial forecas'!N15*'Model inputs'!AM43 -> 29750 | O19: ='POA — Monthly financial forecas'!O15*'Model inputs'!AM43 -> 36400 | P19: ='POA — Monthly financial forecas'!P15*'Model inputs'!AM43 -> 43050 | Q19: ='POA — Monthly financial forecas'!Q15*'Model inputs'!AM43 -> 49700 | R19: ='POA — Monthly financial forecas'!R15*'Model inputs'!AM43 -> 56350 | S19: ='POA — Monthly financial forecas'!S15*'Model inputs'!AM43 -> 63000 | T19: ='POA — Monthly financial forecas'!T15*'Model inputs'!AM43 -> 70000 | U19: ='POA — Monthly financial forecas'!U15*'Model inputs'!AM43 -> 77000 | V19: ='POA — Monthly financial forecas'!V15*'Model inputs'!AM43 -> 84000 | W19: ='POA — Monthly financial forecas'!W15*'Model inputs'!AM43 -> 91000 | X19: ='POA — Monthly financial forecas'!X15*'Model inputs'!AM43 -> 98000 | Y19: ='POA — Monthly financial forecas'!Y15*'Model inputs'!AM43 -> 105000 | Z19: ='POA — Monthly financial forecas'!Z15*'Model inputs'!AM43 -> 111125 | AA19: ='POA — Monthly financial forecas'!AA15*'Model inputs'!AM43 -> 117250 | AB19: ='POA — Monthly financial forecas'!AB15*'Model inputs'!AM43 -> 123375 | AC19: ='POA — Monthly financial forecas'!AC15*'Model inputs'!AM43 -> 129500 | AD19: ='POA — Monthly financial forecas'!AD15*'Model inputs'!AM43 -> 135625 | AE19: ='POA — Monthly financial forecas'!AE15*'Model inputs'!AM43 -> 141750 | AF19: ='POA — Monthly financial forecas'!AF15*'Model inputs'!AM43 -> 146125 | AG19: ='POA — Monthly financial forecas'!AG15*'Model inputs'!AM43 -> 150500 | AH19: ='POA — Monthly financial forecas'!AH15*'Model inputs'!AM43 -> 154875 | AI19: ='POA — Monthly financial forecas'!AI15*'Model inputs'!AM43 -> 159250 | AJ19: ='POA — Monthly financial forecas'!AJ15*'Model inputs'!AM43 -> 163625 | AK19: ='POA — Monthly financial forecas'!AK15*'Model inputs'!AM43 -> 168000
A20: Lending | B20: ='POA — Monthly financial forecas'!B16*'Model inputs'!AM43 -> 1400 | C20: ='POA — Monthly financial forecas'!C16*'Model inputs'!AM43 -> 2800 | D20: ='POA — Monthly financial forecas'!D16*'Model inputs'!AM43 -> 4200 | E20: ='POA — Monthly financial forecas'!E16*'Model inputs'!AM43 -> 5600 | F20: ='POA — Monthly financial forecas'!F16*'Model inputs'!AM43 -> 7000 | G20: ='POA — Monthly financial forecas'!G16*'Model inputs'!AM43 -> 8400 | H20: ='POA — Monthly financial forecas'!H16*'Model inputs'!AM43 -> 12133.333 | I20: ='POA — Monthly financial forecas'!I16*'Model inputs'!AM43 -> 15866.667 | J20: ='POA — Monthly financial forecas'!J16*'Model inputs'!AM43 -> 19600 | K20: ='POA — Monthly financial forecas'!K16*'Model inputs'!AM43 -> 23333.333 | L20: ='POA — Monthly financial forecas'!L16*'Model inputs'!AM43 -> 27066.667 | M20: ='POA — Monthly financial forecas'!M16*'Model inputs'!AM43 -> 30800 | N20: ='POA — Monthly financial forecas'!N16*'Model inputs'!AM43 -> 39666.667 | O20: ='POA — Monthly financial forecas'!O16*'Model inputs'!AM43 -> 48533.333 | P20: ='POA — Monthly financial forecas'!P16*'Model inputs'!AM43 -> 57400 | Q20: ='POA — Monthly financial forecas'!Q16*'Model inputs'!AM43 -> 66266.667 | R20: ='POA — Monthly financial forecas'!R16*'Model inputs'!AM43 -> 75133.333 | S20: ='POA — Monthly financial forecas'!S16*'Model inputs'!AM43 -> 84000 | T20: ='POA — Monthly financial forecas'!T16*'Model inputs'!AM43 -> 93333.333 | U20: ='POA — Monthly financial forecas'!U16*'Model inputs'!AM43 -> 102666.67 | V20: ='POA — Monthly financial forecas'!V16*'Model inputs'!AM43 -> 112000 | W20: ='POA — Monthly financial forecas'!W16*'Model inputs'!AM43 -> 121333.33 | X20: ='POA — Monthly financial forecas'!X16*'Model inputs'!AM43 -> 130666.67 | Y20: ='POA — Monthly financial forecas'!Y16*'Model inputs'!AM43 -> 140000 | Z20: ='POA — Monthly financial forecas'!Z16*'Model inputs'!AM43 -> 148166.67 | AA20: ='POA — Monthly financial forecas'!AA16*'Model inputs'!AM43 -> 156333.33 | AB20: ='POA — Monthly financial forecas'!AB16*'Model inputs'!AM43 -> 164500 | AC20: ='POA — Monthly financial forecas'!AC16*'Model inputs'!AM43 -> 172666.67 | AD20: ='POA — Monthly financial forecas'!AD16*'Model inputs'!AM43 -> 180833.33 | AE20: ='POA — Monthly financial forecas'!AE16*'Model inputs'!AM43 -> 189000 | AF20: ='POA — Monthly financial forecas'!AF16*'Model inputs'!AM43 -> 194833.33 | AG20: ='POA — Monthly financial forecas'!AG16*'Model inputs'!AM43 -> 200666.67 | AH20: ='POA — Monthly financial forecas'!AH16*'Model inputs'!AM43 -> 206500 | AI20: ='POA — Monthly financial forecas'!AI16*'Model inputs'!AM43 -> 212333.33 | AJ20: ='POA — Monthly financial forecas'!AJ16*'Model inputs'!AM43 -> 218166.67 | AK20: ='POA — Monthly financial forecas'!AK16*'Model inputs'!AM43 -> 224000
A21: Liquid staking | B21: ='POA — Monthly financial forecas'!B17*'Model inputs'!AM43 -> 1050 | C21: ='POA — Monthly financial forecas'!C17*'Model inputs'!AM43 -> 2100 | D21: ='POA — Monthly financial forecas'!D17*'Model inputs'!AM43 -> 3150 | E21: ='POA — Monthly financial forecas'!E17*'Model inputs'!AM43 -> 4200 | F21: ='POA — Monthly financial forecas'!F17*'Model inputs'!AM43 -> 5250 | G21: ='POA — Monthly financial forecas'!G17*'Model inputs'!AM43 -> 6300 | H21: ='POA — Monthly financial forecas'!H17*'Model inputs'!AM43 -> 9100 | I21: ='POA — Monthly financial forecas'!I17*'Model inputs'!AM43 -> 11900 | J21: ='POA — Monthly financial forecas'!J17*'Model inputs'!AM43 -> 14700 | K21: ='POA — Monthly financial forecas'!K17*'Model inputs'!AM43 -> 17500 | L21: ='POA — Monthly financial forecas'!L17*'Model inputs'!AM43 -> 20300 | M21: ='POA — Monthly financial forecas'!M17*'Model inputs'!AM43 -> 23100 | N21: ='POA — Monthly financial forecas'!N17*'Model inputs'!AM43 -> 29750 | O21: ='POA — Monthly financial forecas'!O17*'Model inputs'!AM43 -> 36400 | P21: ='POA — Monthly financial forecas'!P17*'Model inputs'!AM43 -> 43050 | Q21: ='POA — Monthly financial forecas'!Q17*'Model inputs'!AM43 -> 49700 | R21: ='POA — Monthly financial forecas'!R17*'Model inputs'!AM43 -> 56350 | S21: ='POA — Monthly financial forecas'!S17*'Model inputs'!AM43 -> 63000 | T21: ='POA — Monthly financial forecas'!T17*'Model inputs'!AM43 -> 70000 | U21: ='POA — Monthly financial forecas'!U17*'Model inputs'!AM43 -> 77000 | V21: ='POA — Monthly financial forecas'!V17*'Model inputs'!AM43 -> 84000 | W21: ='POA — Monthly financial forecas'!W17*'Model inputs'!AM43 -> 91000 | X21: ='POA — Monthly financial forecas'!X17*'Model inputs'!AM43 -> 98000 | Y21: ='POA — Monthly financial forecas'!Y17*'Model inputs'!AM43 -> 105000 | Z21: ='POA — Monthly financial forecas'!Z17*'Model inputs'!AM43 -> 111125 | AA21: ='POA — Monthly financial forecas'!AA17*'Model inputs'!AM43 -> 117250 | AB21: ='POA — Monthly financial forecas'!AB17*'Model inputs'!AM43 -> 123375 | AC21: ='POA — Monthly financial forecas'!AC17*'Model inputs'!AM43 -> 129500 | AD21: ='POA — Monthly financial forecas'!AD17*'Model inputs'!AM43 -> 135625 | AE21: ='POA — Monthly financial forecas'!AE17*'Model inputs'!AM43 -> 141750 | AF21: ='POA — Monthly financial forecas'!AF17*'Model inputs'!AM43 -> 146125 | AG21: ='POA — Monthly financial forecas'!AG17*'Model inputs'!AM43 -> 150500 | AH21: ='POA — Monthly financial forecas'!AH17*'Model inputs'!AM43 -> 154875 | AI21: ='POA — Monthly financial forecas'!AI17*'Model inputs'!AM43 -> 159250 | AJ21: ='POA — Monthly financial forecas'!AJ17*'Model inputs'!AM43 -> 163625 | AK21: ='POA — Monthly financial forecas'!AK17*'Model inputs'!AM43 -> 168000
A22: Contingency fee revenue | B22: =SUM('POA — Monthly financial forecas'!B23,'POA — Monthly financial forecas'!B24,'POA — Monthly financial forecas'!B25) -> 20.833333 | C22: =SUM('POA — Monthly financial forecas'!C23,'POA — Monthly financial forecas'!C24,'POA — Monthly financial forecas'!C25) -> 83.333333 | D22: =SUM('POA — Monthly financial forecas'!D23,'POA — Monthly financial forecas'!D24,'POA — Monthly financial forecas'!D25) -> 187.5 | E22: =SUM('POA — Monthly financial forecas'!E23,'POA — Monthly financial forecas'!E24,'POA — Monthly financial forecas'!E25) -> 333.33333 | F22: =SUM('POA — Monthly financial forecas'!F23,'POA — Monthly financial forecas'!F24,'POA — Monthly financial forecas'!F25) -> 520.83333 | G22: =SUM('POA — Monthly financial forecas'!G23,'POA — Monthly financial forecas'!G24,'POA — Monthly financial forecas'!G25) -> 750 | H22: =SUM('POA — Monthly financial forecas'!H23,'POA — Monthly financial forecas'!H24,'POA — Monthly financial forecas'!H25) -> 1975.1684 | I22: =SUM('POA — Monthly financial forecas'!I23,'POA — Monthly financial forecas'!I24,'POA — Monthly financial forecas'!I25) -> 3749.1582 | ... AK22: =SUM('POA — Monthly financial forecas'!AK23,'POA — Monthly financial forecas'!AK24,'POA — Monthly financial forecas'!AK25) -> 320000
A23: DEX | B23: ='POA — Monthly financial forecas'!B15*'POA — Monthly financial forecas'!B13 -> 6.25 | C23: ='POA — Monthly financial forecas'!C15*'POA — Monthly financial forecas'!C13 -> 25 | D23: ='POA — Monthly financial forecas'!D15*'POA — Monthly financial forecas'!D13 -> 56.25 | E23: ='POA — Monthly financial forecas'!E15*'POA — Monthly financial forecas'!E13 -> 100 | F23: ='POA — Monthly financial forecas'!F15*'POA — Monthly financial forecas'!F13 -> 156.25 | G23: ='POA — Monthly financial forecas'!G15*'POA — Monthly financial forecas'!G13 -> 225 | H23: ='POA — Monthly financial forecas'!H15*'POA — Monthly financial forecas'!H13 -> 592.55051 | I23: ='POA — Monthly financial forecas'!I15*'POA — Monthly financial forecas'!I13 -> 1124.7475 | ... AK23: ='POA — Monthly financial forecas'!AK15*'POA — Monthly financial forecas'!AK13 -> 96000
A24: Lending | B24: ='POA — Monthly financial forecas'!B16*'POA — Monthly financial forecas'!B13 -> 8.3333333 | C24: ='POA — Monthly financial forecas'!C16*'POA — Monthly financial forecas'!C13 -> 33.333333 | D24: ='POA — Monthly financial forecas'!D16*'POA — Monthly financial forecas'!D13 -> 75 | E24: ='POA — Monthly financial forecas'!E16*'POA — Monthly financial forecas'!E13 -> 133.33333 | F24: ='POA — Monthly financial forecas'!F16*'POA — Monthly financial forecas'!F13 -> 208.33333 | G24: ='POA — Monthly financial forecas'!G16*'POA — Monthly financial forecas'!G13 -> 300 | H24: ='POA — Monthly financial forecas'!H16*'POA — Monthly financial forecas'!H13 -> 790.06734 | I24: ='POA — Monthly financial forecas'!I16*'POA — Monthly financial forecas'!I13 -> 1499.6633 | ... AK24: ='POA — Monthly financial forecas'!AK16*'POA — Monthly financial forecas'!AK13 -> 128000
A25: Liquid staking | B25: ='POA — Monthly financial forecas'!B17*'POA — Monthly financial forecas'!B13 -> 6.25 | C25: ='POA — Monthly financial forecas'!C17*'POA — Monthly financial forecas'!C13 -> 25 | D25: ='POA — Monthly financial forecas'!D17*'POA — Monthly financial forecas'!D13 -> 56.25 | E25: ='POA — Monthly financial forecas'!E17*'POA — Monthly financial forecas'!E13 -> 100 | F25: ='POA — Monthly financial forecas'!F17*'POA — Monthly financial forecas'!F13 -> 156.25 | G25: ='POA — Monthly financial forecas'!G17*'POA — Monthly financial forecas'!G13 -> 225 | H25: ='POA — Monthly financial forecas'!H17*'POA — Monthly financial forecas'!H13 -> 592.55051 | I25: ='POA — Monthly financial forecas'!I17*'POA — Monthly financial forecas'!I13 -> 1124.7475 | ... AK25: ='POA — Monthly financial forecas'!AK17*'POA — Monthly financial forecas'!AK13 -> 96000
A26: Verified losses recovered and disbursed | B26: ='POA — Monthly financial forecas'!B22/'Model inputs'!AM14 -> 416.66667 | C26: ='POA — Monthly financial forecas'!C22/'Model inputs'!AM14 -> 1666.6667 | D26: ='POA — Monthly financial forecas'!D22/'Model inputs'!AM14 -> 3750 | E26: ='POA — Monthly financial forecas'!E22/'Model inputs'!AM14 -> 6666.6667 | F26: ='POA — Monthly financial forecas'!F22/'Model inputs'!AM14 -> 10416.667 | G26: ='POA — Monthly financial forecas'!G22/'Model inputs'!AM14 -> 15000 | H26: ='POA — Monthly financial forecas'!H22/'Model inputs'!AM14 -> 39503.367 | I26: ='POA — Monthly financial forecas'!I22/'Model inputs'!AM14 -> 74983.165 | J26: ='POA — Monthly financial forecas'!J22/'Model inputs'!AM14 -> 121439.39 | K26: ='POA — Monthly financial forecas'!K22/'Model inputs'!AM14 -> 178872.05 | L26: ='POA — Monthly financial forecas'!L22/'Model inputs'!AM14 -> 247281.14 | M26: ='POA — Monthly financial forecas'!M22/'Model inputs'!AM14 -> 326666.67 | N26: ='POA — Monthly financial forecas'!N22/'Model inputs'!AM14 -> 468644.78 | O26: ='POA — Monthly financial forecas'!O22/'Model inputs'!AM14 -> 632053.87 | P26: ='POA — Monthly financial forecas'!P22/'Model inputs'!AM14 -> 816893.94 | Q26: ='POA — Monthly financial forecas'!Q22/'Model inputs'!AM14 -> 1023165 | R26: ='POA — Monthly financial forecas'!R22/'Model inputs'!AM14 -> 1250867 | S26: ='POA — Monthly financial forecas'!S22/'Model inputs'!AM14 -> 1500000 | T26: ='POA — Monthly financial forecas'!T22/'Model inputs'!AM14 -> 1722222.2 | U26: ='POA — Monthly financial forecas'!U22/'Model inputs'!AM14 -> 1955555.6 | V26: ='POA — Monthly financial forecas'!V22/'Model inputs'!AM14 -> 2200000 | W26: ='POA — Monthly financial forecas'!W22/'Model inputs'!AM14 -> 2455555.6 | X26: ='POA — Monthly financial forecas'!X22/'Model inputs'!AM14 -> 2722222.2 | Y26: ='POA — Monthly financial forecas'!Y22/'Model inputs'!AM14 -> 3000000 | Z26: ='POA — Monthly financial forecas'!Z22/'Model inputs'!AM14 -> 3263194.4 | AA26: ='POA — Monthly financial forecas'!AA22/'Model inputs'!AM14 -> 3536111.1 | AB26: ='POA — Monthly financial forecas'!AB22/'Model inputs'!AM14 -> 3818750 | AC26: ='POA — Monthly financial forecas'!AC22/'Model inputs'!AM14 -> 4111111.1 | AD26: ='POA — Monthly financial forecas'!AD22/'Model inputs'!AM14 -> 4413194.4 | AE26: ='POA — Monthly financial forecas'!AE22/'Model inputs'!AM14 -> 4725000 | AF26: ='POA — Monthly financial forecas'!AF22/'Model inputs'!AM14 -> 4986805.6 | AG26: ='POA — Monthly financial forecas'!AG22/'Model inputs'!AM14 -> 5255555.6 | AH26: ='POA — Monthly financial forecas'!AH22/'Model inputs'!AM14 -> 5531250 | AI26: ='POA — Monthly financial forecas'!AI22/'Model inputs'!AM14 -> 5813888.9 | AJ26: ='POA — Monthly financial forecas'!AJ22/'Model inputs'!AM14 -> 6103472.2 | AK26: ='POA — Monthly financial forecas'!AK22/'Model inputs'!AM14 -> 6400000
A27: Total revenue | B27: ='POA — Monthly financial forecas'!B18+'POA — Monthly financial forecas'!B22 -> 3520.8333 | C27: ='POA — Monthly financial forecas'!C18+'POA — Monthly financial forecas'!C22 -> 7083.3333 | D27: ='POA — Monthly financial forecas'!D18+'POA — Monthly financial forecas'!D22 -> 10687.5 | E27: ='POA — Monthly financial forecas'!E18+'POA — Monthly financial forecas'!E22 -> 14333.333 | F27: ='POA — Monthly financial forecas'!F18+'POA — Monthly financial forecas'!F22 -> 18020.833 | G27: ='POA — Monthly financial forecas'!G18+'POA — Monthly financial forecas'!G22 -> 21750 | H27: ='POA — Monthly financial forecas'!H18+'POA — Monthly financial forecas'!H22 -> 32308.502 | I27: ='POA — Monthly financial forecas'!I18+'POA — Monthly financial forecas'!I22 -> 43415.825 | ... AK27: ='POA — Monthly financial forecas'!AK18+'POA — Monthly financial forecas'!AK22 -> 880000
A28: Contracted subscription ARR | B28: ='POA — Monthly financial forecas'!B18*12 -> 42000 | C28: ='POA — Monthly financial forecas'!C18*12 -> 84000 | D28: ='POA — Monthly financial forecas'!D18*12 -> 126000 | E28: ='POA — Monthly financial forecas'!E18*12 -> 168000 | F28: ='POA — Monthly financial forecas'!F18*12 -> 210000 | G28: ='POA — Monthly financial forecas'!G18*12 -> 252000 | H28: ='POA — Monthly financial forecas'!H18*12 -> 364000 | I28: ='POA — Monthly financial forecas'!I18*12 -> 476000 | ... AK28: ='POA — Monthly financial forecas'!AK18*12 -> 6720000
A29: Total revenue annualized run rate | B29: ='POA — Monthly financial forecas'!B27*12 -> 42250 | C29: ='POA — Monthly financial forecas'!C27*12 -> 85000 | D29: ='POA — Monthly financial forecas'!D27*12 -> 128250 | E29: ='POA — Monthly financial forecas'!E27*12 -> 172000 | F29: ='POA — Monthly financial forecas'!F27*12 -> 216250 | G29: ='POA — Monthly financial forecas'!G27*12 -> 261000 | H29: ='POA — Monthly financial forecas'!H27*12 -> 387702.02 | I29: ='POA — Monthly financial forecas'!I27*12 -> 520989.9 | ... AK29: ='POA — Monthly financial forecas'!AK27*12 -> 10560000
